Workbook

Sheet RAW_DATA
A1: Order_ID | B1: Date | C1: Buyer_ID | D1: Seller_ID | E1: Driver_ID | F1: Region | G1: Category | H1: Order_Status | I1: Order_Value_MYR | J1: Delivery_Time_mins | K1: SLA_Target_mins | L1: Distance_km | M1: Is_On_Time | N1: Month
A2: ORD-0001 | B2: 45295 | C2: BUY-009 | D2: SEL-004 | E2: DRV-022 | F2: Central | G2: Groceries | H2: Completed | I2: 97.04 | J2: 11 | K2: 45 | L2: 11.4 | M2: Yes | N2: Jan-2024
A3: ORD-0002 | B3: 45298 | C3: BUY-033 | D3: SEL-020 | E3: DRV-001 | F3: Central | G3: Food & Bev | H3: Completed | I3: 88.24 | J3: 12 | K3: 45 | L3: 1.4 | M3: Yes | N3: Jan-2024
A4: ORD-0003 | B4: 45301 | C4: BUY-029 | D4: SEL-019 | E4: DRV-009 | F4: North | G4: Food & Bev | H4: Cancelled | I4: 155.54 | K4: 45 | M4: N/A | N4: Jan-2024
A5: ORD-0004 | B5: 45304 | C5: BUY-049 | D5: SEL-011 | E5: DRV-004 | F5: North | G5: Health | H5: Completed | I5: 87.13 | J5: 51 | K5: 45 | L5: 4.9 | M5: No | N5: Jan-2024
A6: ORD-0005 | B6: 45305 | C6: BUY-047 | D6: SEL-015 | E6: DRV-018 | F6: North | G6: Health | H6: Completed | I6: 285.39 | J6: 52 | K6: 45 | L6: 9.5 | M6: No | N6: Jan-2024
A7: ORD-0006 | B7: 45306 | C7: BUY-041 | D7: SEL-020 | E7: DRV-029 | F7: East | G7: Food & Bev | H7: Cancelled | I7: 113.21 | K7: 45 | M7: N/A | N7: Jan-2024
A8: ORD-0007 | B8: 45309 | C8: BUY-006 | D8: SEL-008 | E8: DRV-028 | F8: North | G8: Health | H8: Completed | I8: 273.98 | J8: 13 | K8: 45 | L8: 10.3 | M8: Yes | N8: Jan-2024
A9: ORD-0008 | B9: 45311 | C9: BUY-024 | D9: SEL-006 | E9: DRV-012 | F9: East | G9: Food & Bev | H9: Cancelled | I9: 227.95 | K9: 45 | M9: N/A | N9: Jan-2024
A10: ORD-0009 | B10: 45314 | C10: BUY-035 | D10: SEL-008 | E10: DRV-006 | F10: West | G10: Health | H10: Completed | I10: 227.72 | J10: 90 | K10: 45 | L10: 2 | M10: No | N10: Jan-2024
A11: ORD-0010 | B11: 45316 | C11: BUY-021 | D11: SEL-002 | E11: DRV-008 | F11: North | G11: Electronics | H11: Cancelled | I11: 88.57 | K11: 45 | M11: N/A | N11: Jan-2024
A12: ORD-0011 | B12: 45318 | C12: BUY-046 | D12: SEL-011 | E12: DRV-007 | F12: West | G12: Health | H12: Completed | I12: 330.87 | J12: 16 | K12: 45 | L12: 4 | M12: Yes | N12: Jan-2024
A13: ORD-0012 | B13: 45321 | C13: BUY-009 | D13: SEL-008 | E13: DRV-024 | F13: Central | G13: Electronics | H13: Cancelled | I13: 62.86 | K13: 45 | M13: N/A | N13: Jan-2024
A14: ORD-0013 | B14: 45324 | C14: BUY-015 | D14: SEL-005 | E14: DRV-017 | F14: West | G14: Groceries | H14: Late | I14: 148.8 | J14: 62 | K14: 45 | L14: 13.6 | M14: No | N14: Feb-2024
A15: ORD-0014 | B15: 45325 | C15: BUY-028 | D15: SEL-020 | E15: DRV-003 | F15: West | G15: Health | H15: Completed | I15: 280.35 | J15: 27 | K15: 45 | L15: 9.8 | M15: Yes | N15: Feb-2024
A16: ORD-0015 | B16: 45328 | C16: BUY-036 | D16: SEL-001 | E16: DRV-022 | F16: North | G16: Electronics | H16: Cancelled | I16: 192.25 | K16: 45 | M16: N/A | N16: Feb-2024
A17: ORD-0016 | B17: 45331 | C17: BUY-001 | D17: SEL-009 | E17: DRV-017 | F17: South | G17: Groceries | H17: Completed | I17: 67.98 | J17: 22 | K17: 45 | L17: 5.1 | M17: Yes | N17: Feb-2024
A18: ORD-0017 | B18: 45334 | C18: BUY-024 | D18: SEL-006 | E18: DRV-018 | F18: Central | G18: Groceries | H18: Completed | I18: 81.64 | J18: 89 | K18: 45 | L18: 8.1 | M18: No | N18: Feb-2024
A19: ORD-0018 | B19: 45337 | C19: BUY-020 | D19: SEL-008 | E19: DRV-002 | F19: South | G19: Groceries | H19: Completed | I19: 326.25 | J19: 70 | K19: 45 | L19: 1.3 | M19: No | N19: Feb-2024
A20: ORD-0019 | B20: 45338 | C20: BUY-049 | D20: SEL-018 | E20: DRV-025 | F20: South | G20: Food & Bev | H20: Cancelled | I20: 288.37 | K20: 45 | M20: N/A | N20: Feb-2024
A21: ORD-0020 | B21: 45341 | C21: BUY-011 | D21: SEL-009 | E21: DRV-017 | F21: Central | G21: Health | H21: Cancelled | I21: 332.19 | K21: 45 | M21: N/A | N21: Feb-2024
A22: ORD-0021 | B22: 45342 | C22: BUY-045 | D22: SEL-007 | E22: DRV-023 | F22: East | G22: Health | H22: Cancelled | I22: 268.01 | K22: 45 | M22: N/A | N22: Feb-2024
A23: ORD-0022 | B23: 45345 | C23: BUY-016 | D23: SEL-008 | E23: DRV-003 | F23: East | G23: Groceries | H23: Completed | I23: 166.25 | J23: 64 | K23: 45 | L23: 13.6 | M23: No | N23: Feb-2024
A24: ORD-0023 | B24: 45348 | C24: BUY-015 | D24: SEL-001 | E24: DRV-003 | F24: North | G24: Food & Bev | H24: Cancelled | I24: 92.09 | K24: 45 | M24: N/A | N24: Feb-2024
A25: ORD-0024 | B25: 45349 | C25: BUY-043 | D25: SEL-016 | E25: DRV-007 | F25: Central | G25: Food & Bev | H25: Completed | I25: 94.73 | J25: 50 | K25: 45 | L25: 2 | M25: No | N25: Feb-2024
A26: ORD-0025 | B26: 45352 | C26: BUY-027 | D26: SEL-007 | E26: DRV-004 | F26: North | G26: Health | H26: Late | I26: 277.85 | J26: 81 | K26: 45 | L26: 7.6 | M26: No | N26: Mar-2024
A27: ORD-0026 | B27: 45354 | C27: BUY-044 | D27: SEL-004 | E27: DRV-002 | F27: West | G27: Electronics | H27: Completed | I27: 259.24 | J27: 60 | K27: 45 | L27: 7.5 | M27: No | N27: Mar-2024
A28: ORD-0027 | B28: 45355 | C28: BUY-028 | D28: SEL-006 | E28: DRV-009 | F28: West | G28: Food & Bev | H28: Completed | I28: 165.29 | J28: 32 | K28: 45 | L28: 3.7 | M28: Yes | N28: Mar-2024
A29: ORD-0028 | B29: 45356 | C29: BUY-036 | D29: SEL-004 | E29: DRV-002 | F29: Central | G29: Groceries | H29: Cancelled | I29: 285.69 | K29: 45 | M29: N/A | N29: Mar-2024
A30: ORD-0029 | B30: 45357 | C30: BUY-026 | D30: SEL-002 | E30: DRV-006 | F30: West | G30: Groceries | H30: Completed | I30: 176.26 | J30: 29 | K30: 45 | L30: 6.7 | M30: Yes | N30: Mar-2024
A31: ORD-0030 | B31: 45359 | C31: BUY-047 | D31: SEL-018 | E31: DRV-022 | F31: West | G31: Food & Bev | H31: Completed | I31: 248.36 | J31: 66 | K31: 45 | L31: 5 | M31: No | N31: Mar-2024
A32: ORD-0031 | B32: 45360 | C32: BUY-035 | D32: SEL-002 | E32: DRV-024 | F32: East | G32: Groceries | H32: Completed | I32: 209.03 | J32: 35 | K32: 45 | L32: 14.6 | M32: Yes | N32: Mar-2024
A33: ORD-0032 | B33: 45361 | C33: BUY-011 | D33: SEL-002 | E33: DRV-017 | F33: North | G33: Food & Bev | H33: Late | I33: 300.66 | J33: 69 | K33: 45 | L33: 8 | M33: No | N33: Mar-2024
A34: ORD-0033 | B34: 45362 | C34: BUY-008 | D34: SEL-019 | E34: DRV-008 | F34: Central | G34: Groceries | H34: Late | I34: 93.79 | J34: 16 | K34: 45 | L34: 10.5 | M34: Yes | N34: Mar-2024
A35: ORD-0034 | B35: 45365 | C35: BUY-021 | D35: SEL-009 | E35: DRV-007 | F35: East | G35: Food & Bev | H35: Completed | I35: 204.35 | J35: 61 | K35: 45 | L35: 10.2 | M35: No | N35: Mar-2024
A36: ORD-0035 | B36: 45367 | C36: BUY-021 | D36: SEL-003 | E36: DRV-001 | F36: West | G36: Groceries | H36: Completed | I36: 115.5 | J36: 24 | K36: 45 | L36: 10.4 | M36: Yes | N36: Mar-2024
A37: ORD-0036 | B37: 45368 | C37: BUY-017 | D37: SEL-005 | E37: DRV-030 | F37: East | G37: Groceries | H37: Cancelled | I37: 86.41 | K37: 45 | M37: N/A | N37: Mar-2024
A38: ORD-0037 | B38: 45369 | C38: BUY-046 | D38: SEL-010 | E38: DRV-020 | F38: Central | G38: Groceries | H38: Completed | I38: 294.3 | J38: 44 | K38: 45 | L38: 3.2 | M38: Yes | N38: Mar-2024
A39: ORD-0038 | B39: 45372 | C39: BUY-043 | D39: SEL-004 | E39: DRV-029 | F39: South | G39: Electronics | H39: Cancelled | I39: 115.29 | K39: 45 | M39: N/A | N39: Mar-2024
A40: ORD-0039 | B40: 45373 | C40: BUY-014 | D40: SEL-011 | E40: DRV-007 | F40: East | G40: Health | H40: Completed | I40: 109.39 | J40: 78 | K40: 45 | L40: 3.2 | M40: No | N40: Mar-2024
...

Sheet KPI_DASHBOARD
A1: ⚡ INSTANT DELIVERY — KPI DASHBOARD
A2: Reporting Period: | E2: Jan 2024 – Jun 2024 | I2: Last Updated: | M2: =TODAY() -> 46133
A4: Total Orders | C4: Completion Rate | E4: On-Time Rate | G4: Avg Delivery (mins) | I4: Total GMV (MYR) | K4: Unique Buyers
A5: =COUNTA(RAW_DATA!A2:A201) -> 200 | C5: =IFERROR(COUNTIF(RAW_DATA!H2:H201,"Completed")/COUNTA(RAW_DATA!A2:A201),0) -> 0.625 | E5: =IFERROR(COUNTIF(RAW_DATA!M2:M201,"Yes")/COUNTIF(RAW_DATA!H2:H201,"Completed"),0) -> 0.496 | G5: =IFERROR(AVERAGEIF(RAW_DATA!H2:H201,"Completed",RAW_DATA!J2:J201),0) -> 49.632 | I5: =IFERROR(SUMIF(RAW_DATA!H2:H201,"Completed",RAW_DATA!I2:I201),0) -> 24001.12 | K5: =IFERROR(SUMPRODUCT(1/COUNTIF(RAW_DATA!C2:C201,RAW_DATA!C2:C201)),0) -> 49
A6: Target: 200 | C6: Target: | E6: Target: | G6: Target: | I6: Target: | K6: Target: 45
A7: 200 | C7: 0.75 | E7: 0.8 | G7: 35 | I7: 25000 | K7: 45
A8: vs Target | C8: vs Target | E8: vs Target | G8: vs Target | I8: vs Target | K8: vs Target
A9: =A5-A7 -> 0 | C9: =C5-C7 -> -0.125 | E9: =E5-E7 -> -0.304 | G9: =G5-G7 -> 14.632 | I9: =I5-I7 -> -998.88 | K9: =K5-K7 -> 4
A12: 📍 REGIONAL PERFORMANCE BREAKDOWN
A13: Region | B13: Total Orders | C13: Completed | D13: Cancelled | E13: Late | F13: Completion Rate | G13: Avg Del. Time (mins) | H13: GMV (MYR)
A14: North | B14: =COUNTIF(RAW_DATA!F2:F201,"North") -> 40 | C14: =COUNTIFS(RAW_DATA!F2:F201,"North",RAW_DATA!H2:H201,"Completed") -> 21 | D14: =COUNTIFS(RAW_DATA!F2:F201,"North",RAW_DATA!H2:H201,"Cancelled") -> 13 | E14: =COUNTIFS(RAW_DATA!F2:F201,"North",RAW_DATA!H2:H201,"Late") -> 6 | F14: =IFERROR(C14/B14,0) -> 0.525 | G14: =IFERROR(AVERAGEIFS(RAW_DATA!J2:J201,RAW_DATA!F2:F201,"North",RAW_DATA!H2:H201,"Completed"),0) -> 48.047619 | H14: =IFERROR(SUMIFS(RAW_DATA!I2:I201,RAW_DATA!F2:F201,"North",RAW_DATA!H2:H201,"Completed"),0) -> 4169.32
A15: South | B15: =COUNTIF(RAW_DATA!F2:F201,"South") -> 32 | C15: =COUNTIFS(RAW_DATA!F2:F201,"South",RAW_DATA!H2:H201,"Completed") -> 21 | D15: =COUNTIFS(RAW_DATA!F2:F201,"South",RAW_DATA!H2:H201,"Cancelled") -> 10 | E15: =COUNTIFS(RAW_DATA!F2:F201,"South",RAW_DATA!H2:H201,"Late") -> 1 | F15: =IFERROR(C15/B15,0) -> 0.65625 | G15: =IFERROR(AVERAGEIFS(RAW_DATA!J2:J201,RAW_DATA!F2:F201,"South",RAW_DATA!H2:H201,"Completed"),0) -> 52.809524 | H15: =IFERROR(SUMIFS(RAW_DATA!I2:I201,RAW_DATA!F2:F201,"South",RAW_DATA!H2:H201,"Completed"),0) -> 3810.53
A16: East | B16: =COUNTIF(RAW_DATA!F2:F201,"East") -> 42 | C16: =COUNTIFS(RAW_DATA!F2:F201,"East",RAW_DATA!H2:H201,"Completed") -> 25 | D16: =COUNTIFS(RAW_DATA!F2:F201,"East",RAW_DATA!H2:H201,"Cancelled") -> 16 | E16: =COUNTIFS(RAW_DATA!F2:F201,"East",RAW_DATA!H2:H201,"Late") -> 1 | F16: =IFERROR(C16/B16,0) -> 0.5952381 | G16: =IFERROR(AVERAGEIFS(RAW_DATA!J2:J201,RAW_DATA!F2:F201,"East",RAW_DATA!H2:H201,"Completed"),0) -> 58.16 | H16: =IFERROR(SUMIFS(RAW_DATA!I2:I201,RAW_DATA!F2:F201,"East",RAW_DATA!H2:H201,"Completed"),0) -> 5032.48
A17: West | B17: =COUNTIF(RAW_DATA!F2:F201,"West") -> 44 | C17: =COUNTIFS(RAW_DATA!F2:F201,"West",RAW_DATA!H2:H201,"Completed") -> 33 | D17: =COUNTIFS(RAW_DATA!F2:F201,"West",RAW_DATA!H2:H201,"Cancelled") -> 5 | E17: =COUNTIFS(RAW_DATA!F2:F201,"West",RAW_DATA!H2:H201,"Late") -> 6 | F17: =IFERROR(C17/B17,0) -> 0.75 | G17: =IFERROR(AVERAGEIFS(RAW_DATA!J2:J201,RAW_DATA!F2:F201,"West",RAW_DATA!H2:H201,"Completed"),0) -> 48.363636 | H17: =IFERROR(SUMIFS(RAW_DATA!I2:I201,RAW_DATA!F2:F201,"West",RAW_DATA!H2:H201,"Completed"),0) -> 6616.47
A18: Central | B18: =COUNTIF(RAW_DATA!F2:F201,"Central") -> 42 | C18: =COUNTIFS(RAW_DATA!F2:F201,"Central",RAW_DATA!H2:H201,"Completed") -> 25 | D18: =COUNTIFS(RAW_DATA!F2:F201,"Central",RAW_DATA!H2:H201,"Cancelled") -> 13 | E18: =COUNTIFS(RAW_DATA!F2:F201,"Central",RAW_DATA!H2:H201,"Late") -> 4 | F18: =IFERROR(C18/B18,0) -> 0.5952381 | G18: =IFERROR(AVERAGEIFS(RAW_DATA!J2:J201,RAW_DATA!F2:F201,"Central",RAW_DATA!H2:H201,"Completed"),0) -> 41.44 | H18: =IFERROR(SUMIFS(RAW_DATA!I2:I201,RAW_DATA!F2:F201,"Central",RAW_DATA!H2:H201,"Completed"),0) -> 4372.32
A19: TOTAL | B19: =SUM(B14:B18) -> 200 | C19: =SUM(C14:C18) -> 125 | D19: =SUM(D14:D18) -> 57 | E19: =SUM(E14:E18) -> 18 | F19: =IFERROR(C19/B19,0) -> 0.625 | G19: =IFERROR(AVERAGE(G14:G18),0) -> 49.764156 | H19: =SUM(H14:H18) -> 24001.12
A22: 📅 MONTHLY TREND SUMMARY
A23: Month | B23: Total Orders | C23: Completed | D23: Cancelled | E23: Late | F23: On-Time Rate | G23: Avg Del. Time | H23: GMV (MYR)
A24: Jan-2024 | B24: =COUNTIF(RAW_DATA!N2:N201,"Jan-2024") -> 12 | C24: =COUNTIFS(RAW_DATA!N2:N201,"Jan-2024",RAW_DATA!H2:H201,"Completed") -> 7 | D24: =COUNTIFS(RAW_DATA!N2:N201,"Jan-2024",RAW_DATA!H2:H201,"Cancelled") -> 5 | E24: =COUNTIFS(RAW_DATA!N2:N201,"Jan-2024",RAW_DATA!H2:H201,"Late") -> 0 | F24: =IFERROR(COUNTIFS(RAW_DATA!N2:N201,"Jan-2024",RAW_DATA!M2:M201,"Yes")/C24,0) -> 0.57142857 | G24: =IFERROR(AVERAGEIFS(RAW_DATA!J2:J201,RAW_DATA!N2:N201,"Jan-2024",RAW_DATA!H2:H201,"Completed"),0) -> 35 | H24: =IFERROR(SUMIFS(RAW_DATA!I2:I201,RAW_DATA!N2:N201,"Jan-2024",RAW_DATA!H2:H201,"Completed"),0) -> 1390.37
A25: Feb-2024 | B25: =COUNTIF(RAW_DATA!N2:N201,"Feb-2024") -> 12 | C25: =COUNTIFS(RAW_DATA!N2:N201,"Feb-2024",RAW_DATA!H2:H201,"Completed") -> 6 | D25: =COUNTIFS(RAW_DATA!N2:N201,"Feb-2024",RAW_DATA!H2:H201,"Cancelled") -> 5 | E25: =COUNTIFS(RAW_DATA!N2:N201,"Feb-2024",RAW_DATA!H2:H201,"Late") -> 1 | F25: =IFERROR(COUNTIFS(RAW_DATA!N2:N201,"Feb-2024",RAW_DATA!M2:M201,"Yes")/C25,0) -> 0.33333333 | G25: =IFERROR(AVERAGEIFS(RAW_DATA!J2:J201,RAW_DATA!N2:N201,"Feb-2024",RAW_DATA!H2:H201,"Completed"),0) -> 53.666667 | H25: =IFERROR(SUMIFS(RAW_DATA!I2:I201,RAW_DATA!N2:N201,"Feb-2024",RAW_DATA!H2:H201,"Completed"),0) -> 1017.2
A26: Mar-2024 | B26: =COUNTIF(RAW_DATA!N2:N201,"Mar-2024") -> 19 | C26: =COUNTIFS(RAW_DATA!N2:N201,"Mar-2024",RAW_DATA!H2:H201,"Completed") -> 12 | D26: =COUNTIFS(RAW_DATA!N2:N201,"Mar-2024",RAW_DATA!H2:H201,"Cancelled") -> 4 | E26: =COUNTIFS(RAW_DATA!N2:N201,"Mar-2024",RAW_DATA!H2:H201,"Late") -> 3 | F26: =IFERROR(COUNTIFS(RAW_DATA!N2:N201,"Mar-2024",RAW_DATA!M2:M201,"Yes")/C26,0) -> 0.66666667 | G26: =IFERROR(AVERAGEIFS(RAW_DATA!J2:J201,RAW_DATA!N2:N201,"Mar-2024",RAW_DATA!H2:H201,"Completed"),0) -> 44.833333 | H26: =IFERROR(SUMIFS(RAW_DATA!I2:I201,RAW_DATA!N2:N201,"Mar-2024",RAW_DATA!H2:H201,"Completed"),0) -> 2298.62
A27: Apr-2024 | B27: =COUNTIF(RAW_DATA!N2:N201,"Apr-2024") -> 15 | C27: =COUNTIFS(RAW_DATA!N2:N201,"Apr-2024",RAW_DATA!H2:H201,"Completed") -> 10 | D27: =COUNTIFS(RAW_DATA!N2:N201,"Apr-2024",RAW_DATA!H2:H201,"Cancelled") -> 4 | E27: =COUNTIFS(RAW_DATA!N2:N201,"Apr-2024",RAW_DATA!H2:H201,"Late") -> 1 | F27: =IFERROR(COUNTIFS(RAW_DATA!N2:N201,"Apr-2024",RAW_DATA!M2:M201,"Yes")/C27,0) -> 0.9 | G27: =IFERROR(AVERAGEIFS(RAW_DATA!J2:J201,RAW_DATA!N2:N201,"Apr-2024",RAW_DATA!H2:H201,"Completed"),0) -> 39.6 | H27: =IFERROR(SUMIFS(RAW_DATA!I2:I201,RAW_DATA!N2:N201,"Apr-2024",RAW_DATA!H2:H201,"Completed"),0) -> 2232.94
A28: May-2024 | B28: =COUNTIF(RAW_DATA!N2:N201,"May-2024") -> 15 | C28: =COUNTIFS(RAW_DATA!N2:N201,"May-2024",RAW_DATA!H2:H201,"Completed") -> 10 | D28: =COUNTIFS(RAW_DATA!N2:N201,"May-2024",RAW_DATA!H2:H201,"Cancelled") -> 4 | E28: =COUNTIFS(RAW_DATA!N2:N201,"May-2024",RAW_DATA!H2:H201,"Late") -> 1 | F28: =IFERROR(COUNTIFS(RAW_DATA!N2:N201,"May-2024",RAW_DATA!M2:M201,"Yes")/C28,0) -> 0.3 | G28: =IFERROR(AVERAGEIFS(RAW_DATA!J2:J201,RAW_DATA!N2:N201,"May-2024",RAW_DATA!H2:H201,"Completed"),0) -> 55.6 | H28: =IFERROR(SUMIFS(RAW_DATA!I2:I201,RAW_DATA!N2:N201,"May-2024",RAW_DATA!H2:H201,"Completed"),0) -> 1764.76
A29: Jun-2024 | B29: =COUNTIF(RAW_DATA!N2:N201,"Jun-2024") -> 127 | C29: =COUNTIFS(RAW_DATA!N2:N201,"Jun-2024",RAW_DATA!H2:H201,"Completed") -> 80 | D29: =COUNTIFS(RAW_DATA!N2:N201,"Jun-2024",RAW_DATA!H2:H201,"Cancelled") -> 35 | E29: =COUNTIFS(RAW_DATA!N2:N201,"Jun-2024",RAW_DATA!H2:H201,"Late") -> 12 | F29: =IFERROR(COUNTIFS(RAW_DATA!N2:N201,"Jun-2024",RAW_DATA!M2:M201,"Yes")/C29,0) -> 0.45 | G29: =IFERROR(AVERAGEIFS(RAW_DATA!J2:J201,RAW_DATA!N2:N201,"Jun-2024",RAW_DATA!H2:H201,"Completed"),0) -> 51.8375 | H29: =IFERROR(SUMIFS(RAW_DATA!I2:I201,RAW_DATA!N2:N201,"Jun-2024",RAW_DATA!H2:H201,"Completed"),0) -> 15297.23
A30: TOTAL | B30: =SUM(B24:B29) -> 200 | C30: =SUM(C24:C29) -> 125 | D30: =SUM(D24:D29) -> 57 | E30: =SUM(E24:E29) -> 18 | F30: =IFERROR(AVERAGE(F24:F29),0) -> 0.53690476 | G30: =IFERROR(AVERAGE(G24:G29),0) -> 46.75625 | H30: =SUM(H24:H29) -> 24001.12

Sheet FORECASTING
A1: 📈 INSTANT DELIVERY — 6-MONTH FORECAST MODEL
A3: ⚙️ MODEL ASSUMPTIONS (Blue = Editable Inputs)
A4: Base Monthly Orders (Jan 2024) | D4: 180
A5: Monthly Order Growth Rate | D5: 0.08
A6: Average Order Value (MYR) | D6: 52
A7: Completion Rate Assumption | D7: 0.72
A8: Driver Utilisation Target | D8: 0.68
A9: SLA Compliance Target | D9: 0.8
A12: 📊 6-MONTH ORDER & REVENUE PROJECTION
A13: Metric | B13: Jan-2024 | C13: Feb-2024 | D13: Mar-2024 | E13: Apr-2024 | F13: May-2024 | G13: Jun-2024 | H13: H1 Total | I13: Monthly Avg
A14: Projected Orders | B14: =$D$4 -> 180 | C14: =ROUND(B14*(1+$D$5),0) -> 194 | D14: =ROUND(C14*(1+$D$5),0) -> 210 | E14: =ROUND(D14*(1+$D$5),0) -> 227 | F14: =ROUND(E14*(1+$D$5),0) -> 245 | G14: =ROUND(F14*(1+$D$5),0) -> 265 | H14: =SUM(B14:G14) -> 1321 | I14: =IFERROR(H14/6,0) -> 220.16667
A15: Projected GMV (MYR) | B15: =ROUND(B14*$D$6,2) -> 9360 | C15: =ROUND(C14*$D$6,2) -> 10088 | D15: =ROUND(D14*$D$6,2) -> 10920 | E15: =ROUND(E14*$D$6,2) -> 11804 | F15: =ROUND(F14*$D$6,2) -> 12740 | G15: =ROUND(G14*$D$6,2) -> 13780 | H15: =SUM(B15:G15) -> 68692 | I15: =IFERROR(H15/6,0) -> 11448.667
A16: Completed Orders | B16: =ROUND(B14*$D$7,0) -> 130 | C16: =ROUND(C14*$D$7,0) -> 140 | D16: =ROUND(D14*$D$7,0) -> 151 | E16: =ROUND(E14*$D$7,0) -> 163 | F16: =ROUND(F14*$D$7,0) -> 176 | G16: =ROUND(G14*$D$7,0) -> 191 | H16: =SUM(B16:G16) -> 951 | I16: =IFERROR(H16/6,0) -> 158.5
A17: Cancelled Orders | B17: =ROUND(B14*(1-$D$7),0) -> 50 | C17: =ROUND(C14*(1-$D$7),0) -> 54 | D17: =ROUND(D14*(1-$D$7),0) -> 59 | E17: =ROUND(E14*(1-$D$7),0) -> 64 | F17: =ROUND(F14*(1-$D$7),0) -> 69 | G17: =ROUND(G14*(1-$D$7),0) -> 74 | H17: =SUM(B17:G17) -> 370 | I17: =IFERROR(H17/6,0) -> 61.666667
A18: Driver Trips Needed | B18: =IFERROR(ROUND(B16/$D$8,0),0) -> 191 | C18: =IFERROR(ROUND(C16/$D$8,0),0) -> 206 | D18: =IFERROR(ROUND(D16/$D$8,0),0) -> 222 | E18: =IFERROR(ROUND(E16/$D$8,0),0) -> 240 | F18: =IFERROR(ROUND(F16/$D$8,0),0) -> 259 | G18: =IFERROR(ROUND(G16/$D$8,0),0) -> 281 | H18: =SUM(B18:G18) -> 1399 | I18: =IFERROR(H18/6,0) -> 233.16667
A19: On-Time Orders (est.) | B19: =ROUND(B16*$D$9,0) -> 104 | C19: =ROUND(C16*$D$9,0) -> 112 | D19: =ROUND(D16*$D$9,0) -> 121 | E19: =ROUND(E16*$D$9,0) -> 130 | F19: =ROUND(F16*$D$9,0) -> 141 | G19: =ROUND(G16*$D$9,0) -> 153 | H19: =SUM(B19:G19) -> 761 | I19: =IFERROR(H19/6,0) -> 126.83333
A22: 📉 ACTUALS vs FORECAST VARIANCE ANALYSIS
A23: Metric | B23: Forecast (H1) | C23: Actual (H1) | D23: Variance | E23: Variance % | F23: Status
A24: Total Orders | B24: =H14 -> 1321 | C24: =COUNTA(RAW_DATA!A2:A201) -> 200 | D24: =C24-B24 -> -1121 | E24: =IFERROR(D24/B24,0) -> -0.84859955 | F24: =IF(D24>=0,"✅ On/Above Target","⚠️ Below Target") -> ⚠️ Below Target
A25: Total GMV (MYR) | B25: =H15 -> 68692 | C25: =IFERROR(SUMIF(RAW_DATA!H2:H201,"Completed",RAW_DATA!I2:I201),0) -> 24001.12 | D25: =C25-B25 -> -44690.88 | E25: =IFERROR(D25/B25,0) -> -0.65059803 | F25: =IF(D25>=0,"✅ On/Above Target","⚠️ Below Target") -> ⚠️ Below Target
A26: Completed Orders | B26: =H16 -> 951 | C26: =IFERROR(COUNTIF(RAW_DATA!H2:H201,"Completed"),0) -> 125 | D26: =C26-B26 -> -826 | E26: =IFERROR(D26/B26,0) -> -0.86855941 | F26: =IF(D26>=0,"✅ On/Above Target","⚠️ Below Target") -> ⚠️ Below Target

Sheet PIVOT_ANALYSIS
A1: 🔄 PIVOT ANALYSIS — ORDERS BY REGION & CATEGORY
A3: Pivot 1 — Order Count by Region × Category
A4: Region \ Category | B4: Groceries | C4: Food & Bev | D4: Electronics | E4: Health | F4: TOTAL
A5: North | B5: =COUNTIFS(RAW_DATA!F2:F201,"North",RAW_DATA!G2:G201,"Groceries") -> 10 | C5: =COUNTIFS(RAW_DATA!F2:F201,"North",RAW_DATA!G2:G201,"Food & Bev") -> 11 | D5: =COUNTIFS(RAW_DATA!F2:F201,"North",RAW_DATA!G2:G201,"Electronics") -> 6 | E5: =COUNTIFS(RAW_DATA!F2:F201,"North",RAW_DATA!G2:G201,"Health") -> 13 | F5: =SUM(B5:E5) -> 40
A6: South | B6: =COUNTIFS(RAW_DATA!F2:F201,"South",RAW_DATA!G2:G201,"Groceries") -> 9 | C6: =COUNTIFS(RAW_DATA!F2:F201,"South",RAW_DATA!G2:G201,"Food & Bev") -> 6 | D6: =COUNTIFS(RAW_DATA!F2:F201,"South",RAW_DATA!G2:G201,"Electronics") -> 9 | E6: =COUNTIFS(RAW_DATA!F2:F201,"South",RAW_DATA!G2:G201,"Health") -> 8 | F6: =SUM(B6:E6) -> 32
A7: East | B7: =COUNTIFS(RAW_DATA!F2:F201,"East",RAW_DATA!G2:G201,"Groceries") -> 15 | C7: =COUNTIFS(RAW_DATA!F2:F201,"East",RAW_DATA!G2:G201,"Food & Bev") -> 10 | D7: =COUNTIFS(RAW_DATA!F2:F201,"East",RAW_DATA!G2:G201,"Electronics") -> 5 | E7: =COUNTIFS(RAW_DATA!F2:F201,"East",RAW_DATA!G2:G201,"Health") -> 12 | F7: =SUM(B7:E7) -> 42
A8: West | B8: =COUNTIFS(RAW_DATA!F2:F201,"West",RAW_DATA!G2:G201,"Groceries") -> 10 | C8: =COUNTIFS(RAW_DATA!F2:F201,"West",RAW_DATA!G2:G201,"Food & Bev") -> 10 | D8: =COUNTIFS(RAW_DATA!F2:F201,"West",RAW_DATA!G2:G201,"Electronics") -> 13 | E8: =COUNTIFS(RAW_DATA!F2:F201,"West",RAW_DATA!G2:G201,"Health") -> 11 | F8: =SUM(B8:E8) -> 44
A9: Central | B9: =COUNTIFS(RAW_DATA!F2:F201,"Central",RAW_DATA!G2:G201,"Groceries") -> 16 | C9: =COUNTIFS(RAW_DATA!F2:F201,"Central",RAW_DATA!G2:G201,"Food & Bev") -> 10 | D9: =COUNTIFS(RAW_DATA!F2:F201,"Central",RAW_DATA!G2:G201,"Electronics") -> 5 | E9: =COUNTIFS(RAW_DATA!F2:F201,"Central",RAW_DATA!G2:G201,"Health") -> 11 | F9: =SUM(B9:E9) -> 42
A10: TOTAL | B10: =SUM(B5:B9) -> 60 | C10: =SUM(C5:C9) -> 47 | D10: =SUM(D5:D9) -> 38 | E10: =SUM(E5:E9) -> 55 | F10: =SUM(F5:F9) -> 200
A13: Pivot 2 — GMV (MYR) by Region × Month (Completed Orders Only)
A14: Region \ Month | B14: Jan-2024 | C14: Feb-2024 | D14: Mar-2024 | E14: Apr-2024 | F14: May-2024 | G14: Jun-2024 | H14: H1 TOTAL
A15: North | B15: =IFERROR(SUMIFS(RAW_DATA!I2:I201,RAW_DATA!F2:F201,"North",RAW_DATA!N2:N201,"Jan-2024",RAW_DATA!H2:H201,"Completed"),0) -> 646.5 | C15: =IFERROR(SUMIFS(RAW_DATA!I2:I201,RAW_DATA!F2:F201,"North",RAW_DATA!N2:N201,"Feb-2024",RAW_DATA!H2:H201,"Completed"),0) -> 0 | D15: =IFERROR(SUMIFS(RAW_DATA!I2:I201,RAW_DATA!F2:F201,"North",RAW_DATA!N2:N201,"Mar-2024",RAW_DATA!H2:H201,"Completed"),0) -> 0 | E15: =IFERROR(SUMIFS(RAW_DATA!I2:I201,RAW_DATA!F2:F201,"North",RAW_DATA!N2:N201,"Apr-2024",RAW_DATA!H2:H201,"Completed"),0) -> 97.02 | F15: =IFERROR(SUMIFS(RAW_DATA!I2:I201,RAW_DATA!F2:F201,"North",RAW_DATA!N2:N201,"May-2024",RAW_DATA!H2:H201,"Completed"),0) -> 556.8 | G15: =IFERROR(SUMIFS(RAW_DATA!I2:I201,RAW_DATA!F2:F201,"North",RAW_DATA!N2:N201,"Jun-2024",RAW_DATA!H2:H201,"Completed"),0) -> 2869 | H15: =SUM(B15:G15) -> 4169.32
A16: South | B16: =IFERROR(SUMIFS(RAW_DATA!I2:I201,RAW_DATA!F2:F201,"South",RAW_DATA!N2:N201,"Jan-2024",RAW_DATA!H2:H201,"Completed"),0) -> 0 | C16: =IFERROR(SUMIFS(RAW_DATA!I2:I201,RAW_DATA!F2:F201,"South",RAW_DATA!N2:N201,"Feb-2024",RAW_DATA!H2:H201,"Completed"),0) -> 394.23 | D16: =IFERROR(SUMIFS(RAW_DATA!I2:I201,RAW_DATA!F2:F201,"South",RAW_DATA!N2:N201,"Mar-2024",RAW_DATA!H2:H201,"Completed"),0) -> 431.52 | E16: =IFERROR(SUMIFS(RAW_DATA!I2:I201,RAW_DATA!F2:F201,"South",RAW_DATA!N2:N201,"Apr-2024",RAW_DATA!H2:H201,"Completed"),0) -> 669.43 | F16: =IFERROR(SUMIFS(RAW_DATA!I2:I201,RAW_DATA!F2:F201,"South",RAW_DATA!N2:N201,"May-2024",RAW_DATA!H2:H201,"Completed"),0) -> 336.3 | G16: =IFERROR(SUMIFS(RAW_DATA!I2:I201,RAW_DATA!F2:F201,"South",RAW_DATA!N2:N201,"Jun-2024",RAW_DATA!H2:H201,"Completed"),0) -> 1979.05 | H16: =SUM(B16:G16) -> 3810.53
A17: East | B17: =IFERROR(SUMIFS(RAW_DATA!I2:I201,RAW_DATA!F2:F201,"East",RAW_DATA!N2:N201,"Jan-2024",RAW_DATA!H2:H201,"Completed"),0) -> 0 | C17: =IFERROR(SUMIFS(RAW_DATA!I2:I201,RAW_DATA!F2:F201,"East",RAW_DATA!N2:N201,"Feb-2024",RAW_DATA!H2:H201,"Completed"),0) -> 166.25 | D17: =IFERROR(SUMIFS(RAW_DATA!I2:I201,RAW_DATA!F2:F201,"East",RAW_DATA!N2:N201,"Mar-2024",RAW_DATA!H2:H201,"Completed"),0) -> 522.77 | E17: =IFERROR(SUMIFS(RAW_DATA!I2:I201,RAW_DATA!F2:F201,"East",RAW_DATA!N2:N201,"Apr-2024",RAW_DATA!H2:H201,"Completed"),0) -> 485.42 | F17: =IFERROR(SUMIFS(RAW_DATA!I2:I201,RAW_DATA!F2:F201,"East",RAW_DATA!N2:N201,"May-2024",RAW_DATA!H2:H201,"Completed"),0) -> 95.15 | G17: =IFERROR(SUMIFS(RAW_DATA!I2:I201,RAW_DATA!F2:F201,"East",RAW_DATA!N2:N201,"Jun-2024",RAW_DATA!H2:H201,"Completed"),0) -> 3762.89 | H17: =SUM(B17:G17) -> 5032.48
A18: West | B18: =IFERROR(SUMIFS(RAW_DATA!I2:I201,RAW_DATA!F2:F201,"West",RAW_DATA!N2:N201,"Jan-2024",RAW_DATA!H2:H201,"Completed"),0) -> 558.59 | C18: =IFERROR(SUMIFS(RAW_DATA!I2:I201,RAW_DATA!F2:F201,"West",RAW_DATA!N2:N201,"Feb-2024",RAW_DATA!H2:H201,"Completed"),0) -> 280.35 | D18: =IFERROR(SUMIFS(RAW_DATA!I2:I201,RAW_DATA!F2:F201,"West",RAW_DATA!N2:N201,"Mar-2024",RAW_DATA!H2:H201,"Completed"),0) -> 964.65 | E18: =IFERROR(SUMIFS(RAW_DATA!I2:I201,RAW_DATA!F2:F201,"West",RAW_DATA!N2:N201,"Apr-2024",RAW_DATA!H2:H201,"Completed"),0) -> 535.11 | F18: =IFERROR(SUMIFS(RAW_DATA!I2:I201,RAW_DATA!F2:F201,"West",RAW_DATA!N2:N201,"May-2024",RAW_DATA!H2:H201,"Completed"),0) -> 776.51 | G18: =IFERROR(SUMIFS(RAW_DATA!I2:I201,RAW_DATA!F2:F201,"West",RAW_DATA!N2:N201,"Jun-2024",RAW_DATA!H2:H201,"Completed"),0) -> 3501.26 | H18: =SUM(B18:G18) -> 6616.47
A19: Central | B19: =IFERROR(SUMIFS(RAW_DATA!I2:I201,RAW_DATA!F2:F201,"Central",RAW_DATA!N2:N201,"Jan-2024",RAW_DATA!H2:H201,"Completed"),0) -> 185.28 | C19: =IFERROR(SUMIFS(RAW_DATA!I2:I201,RAW_DATA!F2:F201,"Central",RAW_DATA!N2:N201,"Feb-2024",RAW_DATA!H2:H201,"Completed"),0) -> 176.37 | D19: =IFERROR(SUMIFS(RAW_DATA!I2:I201,RAW_DATA!F2:F201,"Central",RAW_DATA!N2:N201,"Mar-2024",RAW_DATA!H2:H201,"Completed"),0) -> 379.68 | E19: =IFERROR(SUMIFS(RAW_DATA!I2:I201,RAW_DATA!F2:F201,"Central",RAW_DATA!N2:N201,"Apr-2024",RAW_DATA!H2:H201,"Completed"),0) -> 445.96 | F19: =IFERROR(SUMIFS(RAW_DATA!I2:I201,RAW_DATA!F2:F201,"Central",RAW_DATA!N2:N201,"May-2024",RAW_DATA!H2:H201,"Completed"),0) -> 0 | G19: =IFERROR(SUMIFS(RAW_DATA!I2:I201,RAW_DATA!F2:F201,"Central",RAW_DATA!N2:N201,"Jun-2024",RAW_DATA!H2:H201,"Completed"),0) -> 3185.03 | H19: =SUM(B19:G19) -> 4372.32
A20: TOTAL | B20: =SUM(B15:B19) -> 1390.37 | C20: =SUM(C15:C19) -> 1017.2 | D20: =SUM(D15:D19) -> 2298.62 | E20: =SUM(E15:E19) -> 2232.94 | F20: =SUM(F15:F19) -> 1764.76 | G20: =SUM(G15:G19) -> 15297.23 | H20: =SUM(H15:H19) -> 24001.12
A23: Pivot 3 — Driver Performance Summary (Top Drivers by Completed Trips)
A24: Driver_ID | B24: Region | C24: Vehicle Type | D24: Completed Trips | E24: Avg Delivery (mins) | F24: On-Time Rate | G24: Performance Tier
A25: DRV-001 | B25: North | C25: Motorcycle | D25: =COUNTIFS(RAW_DATA!E2:E201,"DRV-001",RAW_DATA!H2:H201,"Completed") -> 8 | E25: =IFERROR(AVERAGEIFS(RAW_DATA!J2:J201,RAW_DATA!E2:E201,"DRV-001",RAW_DATA!H2:H201,"Completed"),0) -> 32.875 | F25: =IFERROR(COUNTIFS(RAW_DATA!E2:E201,"DRV-001",RAW_DATA!M2:M201,"Yes")/COUNTIFS(RAW_DATA!E2:E201,"DRV-001",RAW_DATA!H2:H201,"Completed"),0) -> 0.75 | G25: =IF(F25>=0.85,"🏆 Top Performer",IF(F25>=0.7,"✅ Good","⚠️ Needs Improvement")) -> ✅ Good
A26: DRV-002 | B26: South | C26: Motorcycle | D26: =COUNTIFS(RAW_DATA!E2:E201,"DRV-002",RAW_DATA!H2:H201,"Completed") -> 6 | E26: =IFERROR(AVERAGEIFS(RAW_DATA!J2:J201,RAW_DATA!E2:E201,"DRV-002",RAW_DATA!H2:H201,"Completed"),0) -> 49.166667 | F26: =IFERROR(COUNTIFS(RAW_DATA!E2:E201,"DRV-002",RAW_DATA!M2:M201,"Yes")/COUNTIFS(RAW_DATA!E2:E201,"DRV-002",RAW_DATA!H2:H201,"Completed"),0) -> 0.5 | G26: =IF(F26>=0.85,"🏆 Top Performer",IF(F26>=0.7,"✅ Good","⚠️ Needs Improvement")) -> ⚠️ Needs Improvement
A27: DRV-003 | B27: East | C27: Car | D27: =COUNTIFS(RAW_DATA!E2:E201,"DRV-003",RAW_DATA!H2:H201,"Completed") -> 6 | E27: =IFERROR(AVERAGEIFS(RAW_DATA!J2:J201,RAW_DATA!E2:E201,"DRV-003",RAW_DATA!H2:H201,"Completed"),0) -> 52 | F27: =IFERROR(COUNTIFS(RAW_DATA!E2:E201,"DRV-003",RAW_DATA!M2:M201,"Yes")/COUNTIFS(RAW_DATA!E2:E201,"DRV-003",RAW_DATA!H2:H201,"Completed"),0) -> 0.33333333 | G27: =IF(F27>=0.85,"🏆 Top Performer",IF(F27>=0.7,"✅ Good","⚠️ Needs Improvement")) -> ⚠️ Needs Improvement
A28: DRV-004 | B28: West | C28: Motorcycle | D28: =COUNTIFS(RAW_DATA!E2:E201,"DRV-004",RAW_DATA!H2:H201,"Completed") -> 6 | E28: =IFERROR(AVERAGEIFS(RAW_DATA!J2:J201,RAW_DATA!E2:E201,"DRV-004",RAW_DATA!H2:H201,"Completed"),0) -> 64.5 | F28: =IFERROR(COUNTIFS(RAW_DATA!E2:E201,"DRV-004",RAW_DATA!M2:M201,"Yes")/COUNTIFS(RAW_DATA!E2:E201,"DRV-004",RAW_DATA!H2:H201,"Completed"),0) -> 0.16666667 | G28: =IF(F28>=0.85,"🏆 Top Performer",IF(F28>=0.7,"✅ Good","⚠️ Needs Improvement")) -> ⚠️ Needs Improvement
A29: DRV-005 | B29: Central | C29: Bicycle | D29: =COUNTIFS(RAW_DATA!E2:E201,"DRV-005",RAW_DATA!H2:H201,"Completed") -> 2 | E29: =IFERROR(AVERAGEIFS(RAW_DATA!J2:J201,RAW_DATA!E2:E201,"DRV-005",RAW_DATA!H2:H201,"Completed"),0) -> 35 | F29: =IFERROR(COUNTIFS(RAW_DATA!E2:E201,"DRV-005",RAW_DATA!M2:M201,"Yes")/COUNTIFS(RAW_DATA!E2:E201,"DRV-005",RAW_DATA!H2:H201,"Completed"),0) -> 1.5 | G29: =IF(F29>=0.85,"🏆 Top Performer",IF(F29>=0.7,"✅ Good","⚠️ Needs Improvement")) -> 🏆 Top Performer
A30: DRV-006 | B30: North | C30: Motorcycle | D30: =COUNTIFS(RAW_DATA!E2:E201,"DRV-006",RAW_DATA!H2:H201,"Completed") -> 3 | E30: =IFERROR(AVERAGEIFS(RAW_DATA!J2:J201,RAW_DATA!E2:E201,"DRV-006",RAW_DATA!H2:H201,"Completed"),0) -> 64.666667 | F30: =IFERROR(COUNTIFS(RAW_DATA!E2:E201,"DRV-006",RAW_DATA!M2:M201,"Yes")/COUNTIFS(RAW_DATA!E2:E201,"DRV-006",RAW_DATA!H2:H201,"Completed"),0) -> 0.33333333 | G30: =IF(F30>=0.85,"🏆 Top Performer",IF(F30>=0.7,"✅ Good","⚠️ Needs Improvement")) -> ⚠️ Needs Improvement
A31: DRV-007 | B31: South | C31: Car | D31: =COUNTIFS(RAW_DATA!E2:E201,"DRV-007",RAW_DATA!H2:H201,"Completed") -> 7 | E31: =IFERROR(AVERAGEIFS(RAW_DATA!J2:J201,RAW_DATA!E2:E201,"DRV-007",RAW_DATA!H2:H201,"Completed"),0) -> 55.714286 | F31: =IFERROR(COUNTIFS(RAW_DATA!E2:E201,"DRV-007",RAW_DATA!M2:M201,"Yes")/COUNTIFS(RAW_DATA!E2:E201,"DRV-007",RAW_DATA!H2:H201,"Completed"),0) -> 0.28571429 | G31: =IF(F31>=0.85,"🏆 Top Performer",IF(F31>=0.7,"✅ Good","⚠️ Needs Improvement")) -> ⚠️ Needs Improvement
A32: DRV-008 | B32: East | C32: Motorcycle | D32: =COUNTIFS(RAW_DATA!E2:E201,"DRV-008",RAW_DATA!H2:H201,"Completed") -> 4 | E32: =IFERROR(AVERAGEIFS(RAW_DATA!J2:J201,RAW_DATA!E2:E201,"DRV-008",RAW_DATA!H2:H201,"Completed"),0) -> 43 | F32: =IFERROR(COUNTIFS(RAW_DATA!E2:E201,"DRV-008",RAW_DATA!M2:M201,"Yes")/COUNTIFS(RAW_DATA!E2:E201,"DRV-008",RAW_DATA!H2:H201,"Completed"),0) -> 0.75 | G32: =IF(F32>=0.85,"🏆 Top Performer",IF(F32>=0.7,"✅ Good","⚠️ Needs Improvement")) -> ✅ Good
A33: DRV-009 | B33: West | C33: Bicycle | D33: =COUNTIFS(RAW_DATA!E2:E201,"DRV-009",RAW_DATA!H2:H201,"Completed") -> 2 | E33: =IFERROR(AVERAGEIFS(RAW_DATA!J2:J201,RAW_DATA!E2:E201,"DRV-009",RAW_DATA!H2:H201,"Completed"),0) -> 50 | F33: =IFERROR(COUNTIFS(RAW_DATA!E2:E201,"DRV-009",RAW_DATA!M2:M201,"Yes")/COUNTIFS(RAW_DATA!E2:E201,"DRV-009",RAW_DATA!H2:H201,"Completed"),0) -> 0.5 | G33: =IF(F33>=0.85,"🏆 Top Performer",IF(F33>=0.7,"✅ Good","⚠️ Needs Improvement")) -> ⚠️ Needs Improvement
A34: DRV-010 | B34: Central | C34: Motorcycle | D34: =COUNTIFS(RAW_DATA!E2:E201,"DRV-010",RAW_DATA!H2:H201,"Completed") -> 5 | E34: =IFERROR(AVERAGEIFS(RAW_DATA!J2:J201,RAW_DATA!E2:E201,"DRV-010",RAW_DATA!H2:H201,"Completed"),0) -> 64.4 | F34: =IFERROR(COUNTIFS(RAW_DATA!E2:E201,"DRV-010",RAW_DATA!M2:M201,"Yes")/COUNTIFS(RAW_DATA!E2:E201,"DRV-010",RAW_DATA!H2:H201,"Completed"),0) -> 0 | G34: =IF(F34>=0.85,"🏆 Top Performer",IF(F34>=0.7,"✅ Good","⚠️ Needs Improvement")) -> ⚠️ Needs Improvement

Sheet CHARTS
A1: 📊 INSTANT DELIVERY — VISUAL ANALYTICS DASHBOARD
A3: Chart 1 — Monthly Order Volume Trend | J3: Chart 2 — Completion Rate by Region
A4: Month | B4: Orders | C4: Completed | D4: GMV (MYR) | J4: Region | K4: Completion Rate
A5: Jan-2024 | B5: =KPI_DASHBOARD!B24 -> 12 | C5: =KPI_DASHBOARD!C24 -> 7 | D5: =KPI_DASHBOARD!H24 -> 1390.37 | J5: North | K5: =KPI_DASHBOARD!F14 -> 0.525
A6: Feb-2024 | B6: =KPI_DASHBOARD!B25 -> 12 | C6: =KPI_DASHBOARD!C25 -> 6 | D6: =KPI_DASHBOARD!H25 -> 1017.2 | J6: South | K6: =KPI_DASHBOARD!F15 -> 0.65625
A7: Mar-2024 | B7: =KPI_DASHBOARD!B26 -> 19 | C7: =KPI_DASHBOARD!C26 -> 12 | D7: =KPI_DASHBOARD!H26 -> 2298.62 | J7: East | K7: =KPI_DASHBOARD!F16 -> 0.5952381
A8: Apr-2024 | B8: =KPI_DASHBOARD!B27 -> 15 | C8: =KPI_DASHBOARD!C27 -> 10 | D8: =KPI_DASHBOARD!H27 -> 2232.94 | J8: West | K8: =KPI_DASHBOARD!F17 -> 0.75
A9: May-2024 | B9: =KPI_DASHBOARD!B28 -> 15 | C9: =KPI_DASHBOARD!C28 -> 10 | D9: =KPI_DASHBOARD!H28 -> 1764.76 | J9: Central | K9: =KPI_DASHBOARD!F18 -> 0.5952381
A10: Jun-2024 | B10: =KPI_DASHBOARD!B29 -> 127 | C10: =KPI_DASHBOARD!C29 -> 80 | D10: =KPI_DASHBOARD!H29 -> 15297.23
A32: Chart 3 — Monthly GMV (Completed Orders) | J32: Chart 4 — On-Time vs Late Delivery Split
A33: Month | B33: GMV (MYR) | J33: Status | K33: Count
A34: Jan-2024 | B34: =KPI_DASHBOARD!H24 -> 1390.37 | J34: On-Time | K34: =COUNTIF(RAW_DATA!M2:M201,"Yes") -> 62
A35: Feb-2024 | B35: =KPI_DASHBOARD!H25 -> 1017.2 | J35: Late | K35: =COUNTIF(RAW_DATA!M2:M201,"No") -> 81
A36: Mar-2024 | B36: =KPI_DASHBOARD!H26 -> 2298.62 | J36: Cancelled | K36: =COUNTIF(RAW_DATA!H2:H201,"Cancelled") -> 57
A37: Apr-2024 | B37: =KPI_DASHBOARD!H27 -> 2232.94
A38: May-2024 | B38: =KPI_DASHBOARD!H28 -> 1764.76
A39: Jun-2024 | B39: =KPI_DASHBOARD!H29 -> 15297.23
